Traceback (most recent call last):
  File "/home/danbot2/code_5820/data_analysis/lib/python3.10/site-packages/nbclient/client.py", line 778, in _async_poll_for_reply
    msg = await ensure_async(self.kc.shell_channel.get_msg(timeout=new_timeout))
  File "/home/danbot2/code_5820/data_analysis/lib/python3.10/site-packages/jupyter_core/utils/__init__.py", line 182, in ensure_async
    result = await obj
  File "/home/danbot2/code_5820/data_analysis/lib/python3.10/site-packages/jupyter_client/channels.py", line 315, in get_msg
    raise Empty
_queue.Empty

During handling of the above exception, another exception occurred:

Traceback (most recent call last):
  File "/home/danbot2/code_5820/data_analysis/lib/python3.10/site-packages/jupyter_cache/executors/utils.py", line 58, in single_nb_execution
    executenb(
  File "/home/danbot2/code_5820/data_analysis/lib/python3.10/site-packages/nbclient/client.py", line 1305, in execute
    return NotebookClient(nb=nb, resources=resources, km=km, **kwargs).execute()
  File "/home/danbot2/code_5820/data_analysis/lib/python3.10/site-packages/jupyter_core/utils/__init__.py", line 166, in wrapped
    return loop.run_until_complete(inner)
  File "/usr/lib/python3.10/asyncio/base_events.py", line 649, in run_until_complete
    return future.result()
  File "/home/danbot2/code_5820/data_analysis/lib/python3.10/site-packages/nbclient/client.py", line 705, in async_execute
    await self.async_execute_cell(
  File "/home/danbot2/code_5820/data_analysis/lib/python3.10/site-packages/nbclient/client.py", line 1001, in async_execute_cell
    exec_reply = await self.task_poll_for_reply
  File "/home/danbot2/code_5820/data_analysis/lib/python3.10/site-packages/nbclient/client.py", line 802, in _async_poll_for_reply
    error_on_timeout_execute_reply = await self._async_handle_timeout(timeout, cell)
  File "/home/danbot2/code_5820/data_analysis/lib/python3.10/site-packages/nbclient/client.py", line 852, in _async_handle_timeout
    raise CellTimeoutError.error_from_timeout_and_cell(
nbclient.exceptions.CellTimeoutError: A cell timed out while it was being executed, after 30 seconds.
The message was: Cell execution timed out.
Here is a preview of the cell contents:
-------------------
['cm_means, hs_means = [], []', 'for i, row in df.iterrows():', '    mean_runoff = dpf.compute_mean_runoff(row)', "    df.loc[i, 'mean_runoff'] = mean_runoff", '    # check the values against CAMELS']
...
["        # print(row['official_id'], round(mean_runoff, 2), round(camels_q_mean, 2))", '        cm_means.append(camels_q_mean)', '        hs_means.append(mean_runoff)', '', "df.to_csv(os.path.join(BASE_DIR, 'data', attributes_filename), index=False)"]
-------------------

