Traceback (most recent call last):
  File "/home/danbot2/code_5820/data_analysis/lib/python3.10/site-packages/jupyter_cache/executors/utils.py", line 58, in single_nb_execution
    executenb(
  File "/home/danbot2/code_5820/data_analysis/lib/python3.10/site-packages/nbclient/client.py", line 1305, in execute
    return NotebookClient(nb=nb, resources=resources, km=km, **kwargs).execute()
  File "/home/danbot2/code_5820/data_analysis/lib/python3.10/site-packages/jupyter_core/utils/__init__.py", line 166, in wrapped
    return loop.run_until_complete(inner)
  File "/usr/lib/python3.10/asyncio/base_events.py", line 649, in run_until_complete
    return future.result()
  File "/home/danbot2/code_5820/data_analysis/lib/python3.10/site-packages/nbclient/client.py", line 705, in async_execute
    await self.async_execute_cell(
  File "/home/danbot2/code_5820/data_analysis/lib/python3.10/site-packages/nbclient/client.py", line 1058, in async_execute_cell
    await self._check_raise_for_error(cell, cell_index, exec_reply)
  File "/home/danbot2/code_5820/data_analysis/lib/python3.10/site-packages/nbclient/client.py", line 914, in _check_raise_for_error
    raise CellExecutionError.from_cell_and_msg(cell, exec_reply_content)
nbclient.exceptions.CellExecutionError: An error occurred while executing the following cell:
------------------
import os
import pandas as pd
import numpy as np
import geopandas as gpd
from shapely.geometry import Point
from urllib.request import urlopen
import json

from bokeh.plotting import figure, show, output_file, save
from bokeh.io import output_notebook
import xyzservices.providers as xyz
output_notebook()

import data_processing_functions as dpf
------------------


[0;31m---------------------------------------------------------------------------[0m
[0;31mModuleNotFoundError[0m                       Traceback (most recent call last)
Cell [0;32mIn[1], line 14[0m
[1;32m     11[0m [38;5;28;01mimport[39;00m [38;5;21;01mxyzservices[39;00m[38;5;21;01m.[39;00m[38;5;21;01mproviders[39;00m [38;5;28;01mas[39;00m [38;5;21;01mxyz[39;00m
[1;32m     12[0m output_notebook()
[0;32m---> 14[0m [38;5;28;01mimport[39;00m [38;5;21;01mdata_processing_functions[39;00m [38;5;28;01mas[39;00m [38;5;21;01mdpf[39;00m

[0;31mModuleNotFoundError[0m: No module named 'data_processing_functions'

