Traceback (most recent call last):
  File "/home/danbot2/code_5820/data_analysis/lib/python3.10/site-packages/jupyter_cache/executors/utils.py", line 58, in single_nb_execution
    executenb(
  File "/home/danbot2/code_5820/data_analysis/lib/python3.10/site-packages/nbclient/client.py", line 1305, in execute
    return NotebookClient(nb=nb, resources=resources, km=km, **kwargs).execute()
  File "/home/danbot2/code_5820/data_analysis/lib/python3.10/site-packages/jupyter_core/utils/__init__.py", line 166, in wrapped
    return loop.run_until_complete(inner)
  File "/usr/lib/python3.10/asyncio/base_events.py", line 649, in run_until_complete
    return future.result()
  File "/home/danbot2/code_5820/data_analysis/lib/python3.10/site-packages/nbclient/client.py", line 705, in async_execute
    await self.async_execute_cell(
  File "/home/danbot2/code_5820/data_analysis/lib/python3.10/site-packages/nbclient/client.py", line 1058, in async_execute_cell
    await self._check_raise_for_error(cell, cell_index, exec_reply)
  File "/home/danbot2/code_5820/data_analysis/lib/python3.10/site-packages/nbclient/client.py", line 914, in _check_raise_for_error
    raise CellExecutionError.from_cell_and_msg(cell, exec_reply_content)
nbclient.exceptions.CellExecutionError: An error occurred while executing the following cell:
------------------
import os
import pandas as pd
import numpy as np
from time import time

from bokeh.plotting import figure, show
from bokeh.layouts import gridplot
from bokeh.models import ColumnDataSource
from bokeh.io import output_notebook
from bokeh.palettes import Sunset10, Vibrant7, Category20

import xgboost as xgb
xgb.config_context(verbosity=2)

from sklearn.metrics import (
    root_mean_squared_error,
    mean_absolute_error,
    roc_auc_score,
    accuracy_score,
    confusion_matrix,
)

import data_processing_functions as dpf

from scipy.stats import linregress
output_notebook()

BASE_DIR = os.getcwd()
------------------


[0;31m---------------------------------------------------------------------------[0m
[0;31mModuleNotFoundError[0m                       Traceback (most recent call last)
Cell [0;32mIn[1], line 23[0m
[1;32m     13[0m xgb[38;5;241m.[39mconfig_context(verbosity[38;5;241m=[39m[38;5;241m2[39m)
[1;32m     15[0m [38;5;28;01mfrom[39;00m [38;5;21;01msklearn[39;00m[38;5;21;01m.[39;00m[38;5;21;01mmetrics[39;00m [38;5;28;01mimport[39;00m (
[1;32m     16[0m     root_mean_squared_error,
[1;32m     17[0m     mean_absolute_error,
[0;32m   (...)[0m
[1;32m     20[0m     confusion_matrix,
[1;32m     21[0m )
[0;32m---> 23[0m [38;5;28;01mimport[39;00m [38;5;21;01mdata_processing_functions[39;00m [38;5;28;01mas[39;00m [38;5;21;01mdpf[39;00m
[1;32m     25[0m [38;5;28;01mfrom[39;00m [38;5;21;01mscipy[39;00m[38;5;21;01m.[39;00m[38;5;21;01mstats[39;00m [38;5;28;01mimport[39;00m linregress
[1;32m     26[0m output_notebook()

[0;31mModuleNotFoundError[0m: No module named 'data_processing_functions'

